<?xml version="1.0" ?>
<robot name="oa6">
  <link name="torso">
    <origin xyz="0 0 0" rpy="0 0 0"/>
    <visual>
      <origin xyz="0 0.035 0.066" rpy="1.57 0 0"/>
      <geometry name="torso_mesh">
        <mesh filename="package://openarms/urdf/meshes/torso.stl"/>
      </geometry>
      <material name="Red">
        <color rgba="255 0 0 0.6"/>
      </material>
    </visual>
  </link>
  <link name="shoulderlift">
    <origin xyz="0 0 0" rpy="0 0 0"/>
    <visual>
      <origin xyz="-.07 -0.084 0" rpy="0 0 3.14"/>
      <geometry name="shoulderlift_mesh">
        <mesh filename="package://openarms/urdf/meshes/shoulderlift.stl"/>
      </geometry>
      <material name="Orange">
        <color rgba="255 200 0 0.6"/>
      </material>
    </visual>
  </link>
  <joint name="shoulderlift_joint" type="continuous">
    <parent link="torso"/>
    <child link="shoulderlift"/>
    <origin xyz="0.30 0 0" rpy="0 1.57 0"/>
    <axis xyz="1 0 0"/>
  </joint>
</robot>
