<?xml version="1.0" ?>
<robot name="oa9">
  <link name="torso_link">
    <origin xyz="0 0 0" rpy="0 0 0"/>
    <visual>
      <origin xyz="-.07 -.220 0" rpy="-1.57 0 0"/>
      <geometry name="torso_mesh">
        <mesh filename="package://openarms/urdf/oa9/torso.stl"/>
      </geometry>
      <material name="Red">
        <color rgba="0.7 0.0 0.0 1.0"/>
      </material>
    </visual>
  </link>
  <link name="shoulder_link">
    <origin xyz="0 0 0" rpy="0 0 0"/>
    <visual>
      <origin xyz=".061 .0765 -0.084" rpy="0 -1.57 -1.57"/>
      <geometry name="shoulderlift_mesh">
        <mesh filename="package://openarms/urdf/oa9/shoulder-lift.stl"/>
      </geometry>
      <material name="Green"> 
        <color rgba="0.0 0.7 0.0 1.0"/>
      </material>
    </visual>
  </link>
  <link name="upperarm_upperhalf_link">
    <origin xyz="0 0 0" rpy="0 0 0"/>
    <visual>
      <origin xyz="0.129 -0.065 0.153" rpy="-1.57 0 3.14"/>
      <geometry>
        <mesh filename="package://openarms/urdf/oa9/upperarm-upperhalf.stl"/>
      </geometry>
      <material name="Blue">
        <color rgba="0.3 0.3 1.0 1.0"/>
      </material>
    </visual>
  </link>
  <link name="upperarm_lowerhalf_link">
    <origin xyz="0 0 0" rpy="0 0 0"/>
    <visual>
      <origin xyz="0.032 -.042 0.193" rpy="0 0 1.57"/>
      <geometry>
        <mesh filename="package://openarms/urdf/oa9/upperarm-lowerhalf.stl"/>
      </geometry>
      <material name="Yellow">
        <color rgba="0.8 0.8 0.0 1.0"/>
      </material>
    </visual>
  </link>
  <link name="elbow_link">
    <origin xyz="0 0 0" rpy="0 0 0"/>
    <visual>
      <origin xyz="0.145 0.007 0.033" rpy="0 1.57 0"/>
      <geometry>
        <mesh filename="package://openarms/urdf/oa9/elbow.stl"/>
      </geometry>
      <material name="Cyan">
        <color rgba="0.0 0.8 0.8 1.0"/>
      </material>
    </visual>
  </link>
  <link name="lowerarm_middle_link">
    <origin xyz="0 0 0" rpy="0 0 0"/>
    <visual>
      <origin xyz="-0.0325 -0.041 0.148" rpy="0 0 0"/>
      <geometry>
        <mesh filename="package://openarms/urdf/oa9/lowerarm-middle.stl"/>
      </geometry>
      <material name="Magenta">
        <color rgba="0.7 0.0 0.7 1.0"/>
      </material>
    </visual>
  </link>
  <link name="wrist_pitch_link">
    <origin xyz="0 0 0" rpy="0 0 0"/>
    <visual>
      <origin xyz="-0.061 -0.024 -0.033" rpy="1.57 0 -1.57"/>
      <geometry>
        <mesh filename="package://openarms/urdf/oa9/wrist-pitch.stl"/>
      </geometry>
      <material name="Red"/>
    </visual>
  </link>
  <link name="wrist_roll_link">
    <origin xyz="0 0 0" rpy="0 0 0"/>
    <visual>
      <origin xyz="0.0075 -0.057 0.063" rpy="0 0 3.14"/>
      <geometry>
        <mesh filename="package://openarms/urdf/oa9/wrist-roll.stl"/>
      </geometry>
      <material name="Green"/>
    </visual>
  </link>
  <link name="tool_link">
    <origin xyz="0 0 0" rpy="0 0 0"/>
    <visual>
      <origin xyz="0 0 -.05" rpy="0 0 0"/>
      <geometry>
        <box size="0.01 0.01 0.1"/>
      </geometry>
      <material name="Blue"/>
    </visual>
  </link>

  <joint name="shoulder1" type="continuous">
    <parent link="torso_link"/>
    <child link="shoulder_link"/>
    <origin xyz="0 0 0" rpy="0 0 0"/>
    <axis xyz="0 0 1"/>
  </joint>
  <joint name="shoulder2" type="continuous">
    <parent link="shoulder_link"/>
    <child link="upperarm_upperhalf_link"/>
    <origin xyz="0 .1435 -0.119" rpy="0 1.57 3.14"/>
    <axis xyz="0 0 1"/>
  </joint>
  <joint name="shoulder3" type="continuous">
    <parent link="upperarm_upperhalf_link"/>
    <child link="upperarm_lowerhalf_link"/>
    <origin xyz="0 0 0.052" rpy="0 1.57 0"/>
    <axis xyz="0 0 1"/>
  </joint>
  <joint name="elbow" type="continuous">
    <parent link="upperarm_lowerhalf_link"/>
    <child link="elbow_link"/>
    <origin xyz="-0.073 0 0.425" rpy="1.57 3.14 0"/>
    <axis xyz="0 0 1"/>
  </joint>
  <joint name="wrist1" type="continuous">
    <parent link="elbow_link"/>
    <child link="lowerarm_middle_link"/>
    <origin xyz="0 -0.0255 -0.0087" rpy="0 1.57 0"/>
    <axis xyz="0 0 1"/>
  </joint>
  <joint name="wrist2" type="continuous">
    <parent link="lowerarm_middle_link"/>
    <child link="wrist_pitch_link"/>
    <origin xyz="0 0 0.330" rpy="-1.57 1.57 0"/>
    <axis xyz="0 0 1"/>
  </joint>
  <joint name="wrist3" type="continuous">
    <parent link="wrist_pitch_link"/>
    <child link="wrist_roll_link"/>
    <origin xyz="0 0 -0.006" rpy="0 -1.57 0"/>
    <axis xyz="0 0 1"/>
  </joint>
  <joint name="tool" type="fixed">
    <parent link="wrist_roll_link"/>
    <child link="tool_link"/>
    <origin xyz="0 0 0.2" rpy="0 0 0"/>
  </joint>
</robot>

